Workbook

Sheet Lisez-moi
A1: Déclaration d'applicabilité — NotAge
A3: Référence | B3: NTG-SMSI-DDA-001
A4: Version | B4: 1.0
A5: Date | B5: 27/09/2026
A6: Propriétaire | B6: RSSI
A7: Approbateur | B7: Direction générale (CEO)
A8: Classification | B8: Interne (publié à titre de démonstration, entreprise fictive)
A9: Référentiel | B9: ISO/IEC 27001:2022, annexe A (93 mesures) — seuls les numéros et intitulés sont cités
A10: Exigence couverte | B10: ISO/IEC 27001:2022, article 6.1.3 d)
A12: Lecture
A13: Applicable | B13: Oui si la mesure est nécessaire au SMSI de NotAge ; Non avec justification d'exclusion.
A14: Sources | B14: Rxx : réduit le scénario de risque Rxx (registre NTG-SMSI-RSK-002) · LEG : exigence légale ou réglementaire · CTR : exigence contractuelle (clients, clauses DORA) · SMSI : exigence du système de management ou bonne pratique.
A15: Mesure prioritaire | B15: Oui pour les 28 mesures retenues par le plan de traitement des risques (NTG-SMSI-RSK-004).
A16: Statut | B16: Mise en œuvre · Partielle (existe mais incomplète ou non formalisée) · Planifiée (prévue au plan de traitement ou à la feuille de route) · Non applicable.
A17: Référence | B17: Document où la mesure est décrite : POL, GOV, CTX, DOC, RSK, PIL (dossiers du dépôt), PSSI §n (section de la PSSI), PRC-001 (incidents), PRC-002 (accès).

Sheet DdA
A1: Déclaration d'applicabilité — 93 mesures de l'annexe A
A2: NTG-SMSI-DDA-001 v1.0 · 27/09/2026 · approuvée par la direction générale
A4: Mesure | B4: Thème | C4: Intitulé | D4: Applicable | E4: Justification (inclusion ou exclusion) | F4: Sources | G4: Mesure prioritaire | H4: Statut de mise en œuvre | I4: Référence
A5: A.5 — Mesures organisationnelles
A6: 5.1 | B6: Organisationnelles | C6: Politiques de sécurité de l'information | D6: Oui | E6: Politique du SMSI et PSSI approuvées par la direction et déclinées en procédures. | F6: SMSI | G6: — | H6: Mise en œuvre | I6: POL-001, PSSI
A7: 5.2 | B7: Organisationnelles | C7: Fonctions et responsabilités liées à la sécurité de l'information | D7: Oui | E7: Rôles, comité de sécurité et matrice RACI définis et communiqués. | F7: SMSI | G7: — | H7: Mise en œuvre | I7: GOV-001
A8: 5.3 | B8: Organisationnelles | C8: Séparation des tâches | D8: Oui | E8: La RSSI n'administre pas la production ; aucun déploiement sans validation d'un tiers. | F8: R02, R05 | G8: — | H8: Partielle | I8: GOV-001, PSSI §8
A9: 5.4 | B9: Organisationnelles | C9: Responsabilités de la direction | D9: Oui | E9: La direction exige de tous les salariés et prestataires l'application de la PSSI. | F9: SMSI | G9: — | H9: Mise en œuvre | I9: POL-001
A10: 5.5 | B10: Organisationnelles | C10: Contacts avec les autorités | D10: Oui | E10: Contacts identifiés : CNIL (violations de données), ANSSI et CERT-FR, forces de l'ordre (fraude). | F10: LEG | G10: — | H10: Partielle | I10: PRC-001
A11: 5.6 | B11: Organisationnelles | C11: Contacts avec des groupes d'intérêt spécifiques | D11: Oui | E11: Abonnement aux alertes du CERT-FR et participation à un club de RSSI. | F11: SMSI | G11: — | H11: Planifiée | I11: PSSI §2
A12: 5.7 | B12: Organisationnelles | C12: Renseignement sur les menaces | D12: Oui | E12: Veille sur les menaces visant les éditeurs SaaS et la fraude au virement, intégrée à l'appréciation des risques. | F12: R01, R03 | G12: — | H12: Planifiée | I12: RSK-001
A13: 5.8 | B13: Organisationnelles | C13: Sécurité de l'information dans la gestion de projet | D13: Oui | E13: Analyse de sécurité au lancement de toute fonctionnalité sensible. | F13: R03 | G13: — | H13: Planifiée | I13: PSSI §8
A14: 5.9 | B14: Organisationnelles | C14: Inventaire des informations et autres actifs associés | D14: Oui | E14: Inventaire des actifs primordiaux et supports, avec leurs propriétaires. | F14: SMSI | G14: — | H14: Mise en œuvre | I14: CTX-004
A15: 5.10 | B15: Organisationnelles | C15: Utilisation correcte des informations et autres actifs associés | D15: Oui | E15: Charte d'utilisation des moyens informatiques annexée au règlement intérieur. | F15: R09, R10 | G15: — | H15: Planifiée | I15: PSSI §6
A16: 5.11 | B16: Organisationnelles | C16: Restitution des actifs | D16: Oui | E16: Restitution du matériel vérifiée lors de chaque départ. | F16: R07 | G16: — | H16: Partielle | I16: PRC-002
A17: 5.12 | B17: Organisationnelles | C17: Classification des informations | D17: Oui | E17: Quatre niveaux de classification définis. | F17: SMSI, LEG | G17: — | H17: Mise en œuvre | I17: DOC-001, PSSI §3
... A42: 5.37 | B42: Organisationnelles | C42: Procédures d'exploitation documentées | D42: Oui | E42: Procédures de déploiement, de sauvegarde et de restauration documentées. | F42: R08 | G42: — | H42: Partielle | I42: PSSI §7
A43: A.6 — Mesures liées aux personnes
A44: 6.1 | B44: Liées aux personnes | C44: Sélection des candidats | D44: Oui | E44: Vérifications proportionnées au poste, dans le respect du droit du travail. | F44: LEG | G44: — | H44: Partielle | I44: PSSI §4
A45: 6.2 | B45: Liées aux personnes | C45: Termes et conditions du contrat de travail | D45: Oui | E45: Clauses de sécurité et de confidentialité dans les contrats de travail. | F45: SMSI | G45: — | H45: Mise en œuvre | I45: PSSI §4
A46: 6.3 | B46: Liées aux personnes | C46: Sensibilisation, enseignement et formation | D46: Oui | E46: Sensibilisation à l'arrivée et annuelle, hameçonnage simulé, formation des développeurs. | F46: R09 | G46: Oui | H46: Planifiée | I46: PSSI §4
A47: 6.4 | B47: Liées aux personnes | C47: Processus disciplinaire | D47: Oui | E47: Sanctions prévues au règlement intérieur. | F47: SMSI | G47: — | H47: Mise en œuvre | I47: POL-001
A48: 6.5 | B48: Liées aux personnes | C48: Responsabilités après la fin ou la modification du contrat | D48: Oui | E48: Rappel des obligations de confidentialité et retrait des accès au départ. | F48: R07 | G48: Oui | H48: Planifiée | I48: PRC-002
A49: 6.6 | B49: Liées aux personnes | C49: Engagements de confidentialité ou de non-divulgation | D49: Oui | E49: Engagements de confidentialité signés par les salariés et les prestataires. | F49: R06, CTR | G49: — | H49: Mise en œuvre | I49: PSSI §4
A50: 6.7 | B50: Liées aux personnes | C50: Travail à distance | D50: Oui | E50: Règles de télétravail : réseau, confidentialité, poste géré. | F50: R10 | G50: — | H50: Partielle | I50: PSSI §6
A51: 6.8 | B51: Liées aux personnes | C51: Déclaration des événements de sécurité de l'information | D51: Oui | E51: Canal de signalement unique et simple, connu de tous les salariés. | F51: R09 | G51: Oui | H51: Planifiée | I51: PRC-001
A52: A.7 — Mesures physiques
A53: 7.1 | B53: Physiques | C53: Périmètres de sécurité physique | D53: Oui | E53: Bureaux situés dans un immeuble à accès contrôlé. | F53: SMSI | G53: — | H53: Mise en œuvre | I53: PSSI §6
A54: 7.2 | B54: Physiques | C54: Entrées physiques | D54: Oui | E54: Accès par badge nominatif, visiteurs enregistrés et accompagnés. | F54: SMSI | G54: — | H54: Mise en œuvre | I54: PSSI §6
A55: 7.3 | B55: Physiques | C55: Sécurisation des bureaux, des salles et des installations | D55: Oui | E55: Bureaux fermés à clé en dehors des heures ouvrées. | F55: SMSI | G55: — | H55: Mise en œuvre | I55: PSSI §6
A56: 7.4 | B56: Physiques | C56: Surveillance de la sécurité physique | D56: Oui | E56: Vidéosurveillance et alarme de l'immeuble gérées par le bailleur. | F56: SMSI | G56: — | H56: Mise en œuvre | I56: PSSI §6
A57: 7.5 | B57: Physiques | C57: Protection contre les menaces physiques et environnementales | D57: Oui | E57: Indisponibilité des locaux (crue, canicule) couverte par le télétravail. | F57: R08 | G57: — | H57: Partielle | I57: PSSI §11
A58: 7.6 | B58: Physiques | C58: Travail dans les zones sécurisées | D58: Non | E58: Aucune zone sécurisée dans les locaux : aucun équipement de production n'y est hébergé. La sécurité physique des centres de données relève d'AWS et est maîtrisée par les mesures 5.19 à 5.23. | F58: — | G58: — | H58: Non applicable | I58: —
A59: 7.7 | B59: Physiques | C59: Bureau propre et écran vide | D59: Oui | E59: Verrouillage automatique des sessions, aucun document sensible laissé sur les bureaux. | F59: R10 | G59: — | H59: Partielle | I59: PSSI §6
A60: 7.8 | B60: Physiques | C60: Emplacement et protection du matériel | D60: Oui | E60: Équipement réseau des bureaux dans une baie fermée à clé. | F60: SMSI | G60: — | H60: Mise en œuvre | I60: PSSI §6
A61: 7.9 | B61: Physiques | C61: Sécurité des actifs hors des locaux | D61: Oui | E61: Règles de protection des appareils en déplacement, déclaration de perte sous 24 h. | F61: R10 | G61: Oui | H61: Planifiée | I61: PSSI §6
A62: 7.10 | B62: Physiques | C62: Supports de stockage | D62: Oui | E62: Supports amovibles déconseillés, chiffrés lorsqu'ils sont indispensables. | F62: R10 | G62: — | H62: Partielle | I62: PSSI §6
A63: 7.11 | B63: Physiques | C63: Services supports | D63: Oui | E63: Connexion Internet de secours pour les bureaux ; la plateforme n'en dépend pas. | F63: SMSI | G63: — | H63: Mise en œuvre | I63: PSSI §11
A64: 7.12 | B64: Physiques | C64: Sécurité du câblage | D64: Non | E64: Câblage de l'immeuble géré par le bailleur ; les locaux n'hébergent que des postes de travail et aucun flux de production n'y transite. | F64: — | G64: — | H64: Non applicable | I64: —
... A66: 7.14 | B66: Physiques | C66: Élimination ou recyclage sécurisé du matériel | D66: Oui | E66: Effacement certifié des disques avant recyclage ou réattribution. | F66: LEG | G66: — | H66: Partielle | I66: PSSI §6
...

Sheet Synthèse
A1: Synthèse de la déclaration d'applicabilité
A3: Thème | B3: Mesures | C3: Applicables | D3: Exclues | E3: Mise en œuvre | F3: Partielles | G3: Planifiées | H3: Prioritaires
A4: A.5 Organisationnelles | B4: =COUNTIF(DdA!$B$5:$B$101,"Organisationnelles") -> 37 | C4: =COUNTIFS(DdA!$B$5:$B$101,"Organisationnelles",DdA!$D$5:$D$101,"Oui") -> 37 | D4: =COUNTIFS(DdA!$B$5:$B$101,"Organisationnelles",DdA!$D$5:$D$101,"Non") -> 0 | E4: =COUNTIFS(DdA!$B$5:$B$101,"Organisationnelles",DdA!$H$5:$H$101,"Mise en œuvre") -> 8 | F4: =COUNTIFS(DdA!$B$5:$B$101,"Organisationnelles",DdA!$H$5:$H$101,"Partielle") -> 9 | G4: =COUNTIFS(DdA!$B$5:$B$101,"Organisationnelles",DdA!$H$5:$H$101,"Planifiée") -> 20 | H4: =COUNTIFS(DdA!$B$5:$B$101,"Organisationnelles",DdA!$G$5:$G$101,"Oui") -> 9
A5: A.6 Liées aux personnes | B5: =COUNTIF(DdA!$B$5:$B$101,"Liées aux personnes") -> 8 | C5: =COUNTIFS(DdA!$B$5:$B$101,"Liées aux personnes",DdA!$D$5:$D$101,"Oui") -> 8 | D5: =COUNTIFS(DdA!$B$5:$B$101,"Liées aux personnes",DdA!$D$5:$D$101,"Non") -> 0 | E5: =COUNTIFS(DdA!$B$5:$B$101,"Liées aux personnes",DdA!$H$5:$H$101,"Mise en œuvre") -> 3 | F5: =COUNTIFS(DdA!$B$5:$B$101,"Liées aux personnes",DdA!$H$5:$H$101,"Partielle") -> 2 | G5: =COUNTIFS(DdA!$B$5:$B$101,"Liées aux personnes",DdA!$H$5:$H$101,"Planifiée") -> 3 | H5: =COUNTIFS(DdA!$B$5:$B$101,"Liées aux personnes",DdA!$G$5:$G$101,"Oui") -> 3
A6: A.7 Physiques | B6: =COUNTIF(DdA!$B$5:$B$101,"Physiques") -> 14 | C6: =COUNTIFS(DdA!$B$5:$B$101,"Physiques",DdA!$D$5:$D$101,"Oui") -> 12 | D6: =COUNTIFS(DdA!$B$5:$B$101,"Physiques",DdA!$D$5:$D$101,"Non") -> 2 | E6: =COUNTIFS(DdA!$B$5:$B$101,"Physiques",DdA!$H$5:$H$101,"Mise en œuvre") -> 7 | F6: =COUNTIFS(DdA!$B$5:$B$101,"Physiques",DdA!$H$5:$H$101,"Partielle") -> 4 | G6: =COUNTIFS(DdA!$B$5:$B$101,"Physiques",DdA!$H$5:$H$101,"Planifiée") -> 1 | H6: =COUNTIFS(DdA!$B$5:$B$101,"Physiques",DdA!$G$5:$G$101,"Oui") -> 1
A7: A.8 Technologiques | B7: =COUNTIF(DdA!$B$5:$B$101,"Technologiques") -> 34 | C7: =COUNTIFS(DdA!$B$5:$B$101,"Technologiques",DdA!$D$5:$D$101,"Oui") -> 33 | D7: =COUNTIFS(DdA!$B$5:$B$101,"Technologiques",DdA!$D$5:$D$101,"Non") -> 1 | E7: =COUNTIFS(DdA!$B$5:$B$101,"Technologiques",DdA!$H$5:$H$101,"Mise en œuvre") -> 8 | F7: =COUNTIFS(DdA!$B$5:$B$101,"Technologiques",DdA!$H$5:$H$101,"Partielle") -> 10 | G7: =COUNTIFS(DdA!$B$5:$B$101,"Technologiques",DdA!$H$5:$H$101,"Planifiée") -> 15 | H7: =COUNTIFS(DdA!$B$5:$B$101,"Technologiques",DdA!$G$5:$G$101,"Oui") -> 15
A8: Total | B8: =SUM(B4:B7) -> 93 | C8: =SUM(C4:C7) -> 90 | D8: =SUM(D4:D7) -> 3 | E8: =SUM(E4:E7) -> 26 | F8: =SUM(F4:F7) -> 25 | G8: =SUM(G4:G7) -> 39 | H8: =SUM(H4:H7) -> 28
A10: Taux de mise en œuvre des mesures applicables | B10: =E8/C8 -> 0.28888889
A11: Mise en œuvre + partielles | B11: =(E8+F8)/C8 -> 0.56666667
A13: Lecture : les 28 mesures prioritaires sont celles du plan de traitement des 12 scénarios de risque ; les autres mesures applicables relèvent des exigences légales, contractuelles ou du fonctionnement du SMSI.
